Workbook

Sheet Control de Cambios
A1: Revision | B1: Fecha | C1: Descripción del cambio
A2: 7 | B2: 43242 | C2: Incorporación de columna de separación de cuerpo legal (N° y Descripción) para mejorar identificación y busqueda.
C3: Incorporación de requisitos legales: • D.S Nº 206/1970 Ministerio del Trabajo y Previsión Social Modifica el Decreto Nº54 de 1969, que Aprobó el Reglamento de Comités Paritarios de Higiene y Seguridad: • Decreto Nº 76/06 Ministerio del Trabajo y Previsión Social Aprueba Reglamento para la Aplicación del Artículo Nº 66 Bis de a Ley Nº 16.744 sobre la Gestión de la Seguridad y Salud en el Trabajo en Obras, Faenas o Servicios. • Resolución Exenta Nº 3.457 de 2012 del Ministerio de Salud, que Aprueba la “Guía para la selección y control de protección ocular y facial”, elaborada por el Departamento de Salud Ocupacional del Instituto de Salud Pública. • Resolución Exenta Nº 218 del Ministerio de Salud, que Aprueba instrumento de evaluación de medidas para la prevención de riesgos psicosociales en el trabajo, elaborado por el Departamento de Salud Ocupacional. • D.S. Nº144/1961 Ministerio de Salud. Normas para Evitar Emanaciones o Contaminantes Atmosféricos de Cualquier Naturaleza.. • D.S.Nº103/2000 Ministerio de Transportes y Telecomunicaciones Norma de emisión de hidrocarburos no mecánicos para vehículos livianos y medianos. • D.S. N°149/2007 Ministerio de Transportes y Telecomunicaciones Establece norma de emisión de NO, HC y CO para el control del NOx en vehículos en uso, de encendido por chispa (Ciclo OTTO), que cumplen con las Normas de Emisión Establecidas en el DS. Nº 211. • Resolución N°499/2006, Ministerio de Salud. Aprueba documento electronico de declaración de residuos peligrosos. • Ley 20123, Ministerios del Trabajo y Previsión Social, Regula el trabajo en regimen de subcontratación, el funcionamiento de las empresas de servicios transitorios y el contrato de trabajo de servicios transitorios
C4: Revisión y actualización de cumplimiento de DS 594, DS 18, DS 43, NCh 2056
A5: 8 | B5: 43352 | C5: Incorporación de Leyes al Raglamento Interno de Higiene y Seguridad no contempladas en Matriz Legal: Ley 20584, Ley 20393, Ley 21012, Ley 20830, Ley 20348, Ley 21015, Ley 20422, Ley 19284, Ley 20764, Ley 21042
A6: 9 | B6: 43453 | C6: Incorporación de columna de indicador de menor tiempo de revisión de controles operacionales; además se verifican los controles operacionales de la normativa incluida en la matriz legal. Se actualiza Ordenanza Municipal 35 a 46, tambien se referencia nuevo plano regulador
A7: 10 | B7: 43472 | C7: Se verifican los distintos controles operacionales de toda la normativa aplicable
A8: 11 | B8: 43572 | C8: Se verifican los distintos controles operacionales de toda la normativa aplicable, se incluye NCh2245:2015
A9: 12 | B9: 43598 | C9: Se incorporan Ley 21018 y 21122 , además se verifican los distintos controles operacionales de toda la normativa aplicable
A10: 13 | B10: 43626 | C10: Se verifican los distintos controles operacionales de toda la normativa aplicable
A11: 14 | B11: 43671 | C11: Se verifican los distintos controles operacionales de toda la normativa aplicable
A12: 15 | B12: 43705 | C12: Se verifican los distintos controles operacionales de toda la normativa aplicable
A13: 16 | B13: 43720 | C13: Se incorpora norma técnica 142, además se verifican los distintos controles operacionales de toda la normativa aplicable de acuerdo a su tiempo de revisión.
A14: 17 | B14: 43759 | C14: Se verifican los distintos controles operacionales de toda la normativa aplicable
A15: 18 | B15: 43794 | C15: Se verifican los distintos controles operacionales de toda la normativa aplicable
A16: 19 | B16: 43826 | C16: Se verifican los distintos controles operacionales de toda la normativa aplicable
... A38: 41 | B38: 45939 | C38: 1. Revisión interna, se modifica complementariamente las evidencias de cumplimiento del Decreto 44 2. Se eliminan columnas de Calidad, Ambiente y Seguridad y solo se conserva columna Area, que cumple misma función

Sheet RESUMEN
A1: MATRIZ IDENTIFICACION Y EVALUACION DE REQUISITOS LEGALES | L1: Revisión Área Legal dic-2023, ene-24
A2: ITEM | B2: N°/Código | C2: Titular | D2: Año Publicación | E2: Descripción Cuerpo Legal | F2: Mecanismo de Evaluación | G2: Fecha última Evaluación | H2: Estado de Cumplimiento | I2: Plan de Acción | J2: Estado Plan de Acción | K2: Periodicidad | L2: Vigencia / última modificación | M2: Aplicación general / particular | N2: Área
A3: 1 | B3: Decreto Supremo N° 100 | C3: Ministerio Secretaria General de la Presidencia | D3: 38617 | E3: ='DS 100'!B1 -> DECRETO SUPREMO 100 / 2005, MINISTERIO SECRETARIA GENERAL DE LA PRESIDENCIA, FIJA EL TEXTO REFUNDIDO, COORDINADO Y SISTEMATIZADO DE LA CONSTITUCION POLITICA DE LA REPUBLICA DE CHILE | F3: REVISION DOCUMENTACION | G3: 45512 | H3: ='DS 100'!B2 -> 1 | I3: N/A | J3: No Aplica | K3: Mensual | L3: Vigente. Última modificación 07/11/2023, ley 21.626 (plebiscito constitucional; no aplica a DSS) | M3: General, no sólo los artículos que se indican en el detalle | N3: Calidad / Ambiente / S&ST
A4: 2 | B4: Ley N° 16744 | C4: Ministerio del Trabajo y Previsión Social, Subsecretaría de Previsión Social | D4: 24869 | E4: ='Ley 16,744'!B1 -> Ley Nº 16.744 "Establece Normas sobre Accidentes del Trabajo y Enfermedades Profesionales" | F4: REVISION DOCUMENTACION | G4: 45512 | H4: ='Ley 16,744'!B2 -> 1 | I4: N/A | J4: No Aplica | K4: Mensual | L4: 10/12/2021, ley 21.400 (modifica diversos cuerpos legales para regular, en igualdad de condiciones, el matrimonio entre personas del mismo sexo) | M4: General | N4: Calidad/Ambiente
A5: 3 | B5: D.S. N° 148 | C5: Ministerio de Salud | D5: 38154 | E5: ='DS148'!B1 -> DS 148 APRUEBA REGLAMENTO SANITARIO SOBRE MANEJO DE RESIDUOS PELIGROSOS | F5: INSPECCION | G5: 45512 | H5: ='DS148'!B2 -> 1 | I5: SI | J5: Cerrado | K5: Mensual | L5: Vigente, versión única | M5: General, siempre que la empresa almecene o transporte residuos que la norma contempla como peligrosos | N5: Ambiente
A6: 6 | B6: D.S. N° 594 | C6: Ministerio de Salud | D6: 36645 | E6: ='DS 594'!B1 -> DS 594 "Reglamento sobre condiciones sanitarias y ambientales básicas en los lugares de trabajo" | F6: INSPECCION | G6: 45512 | H6: ='DS 594'!B2 -> 1 | I6: SI | J6: Cerrado | K6: Mensual | L6: Vigente. Última modificación 20/06/2019, Decreto 10 | M6: General | N6: S&ST
A7: 7 | B7: DFL N° 1 | C7: Ministerio de Transporte y telecomunicaciones; Subsecretaría de Transporte; Ministerio de Justicia; Subsecretaría de Justicia | D7: 40115 | E7: DFL 1 FIJA TEXTO REFUNDIDO, COORDINADO Y SISTEMATIZADO DE LA LEY DE TRÁNSITO | F7: REVISION DOCUMENTACION | G7: 45512 | H7: 1 | I7: N/A | J7: No Aplica | K7: Mensual | L7: Vigente. Última modificación ley 21.601 (modifica la ley de tránsito para prevenir la venta de vehículos motorizados robados y sancionar las conductas que indica) | M7: General | N7: S&ST
A8: 8 | B8: Res. Ex. N° 1930 | C8: Ministerio de Defensa Nacional; Subsecretaría de Defensa; Dirección General de Movilización Nacional | D8: 43626 | E8: DEJA SIN EFECTO NORMA CHILENA 2190 DEL AÑO 1993 "SUSTANCIAS PELIGROSAS" Y APRUEBA LA NCH. N° 2190 DE 28.ENE.2019 | F8: INSPECCION | G8: 45512 | H8: 1 | I8: N/A | J8: No Aplica | K8: Mensual | L8: Vigente, versión única | M8: General, siempre que empresa transporte sustancias peligrosas definidas en NCh382 y NCh2120/1 a NCh2120/9 | N8: S&ST
A9: 9 | B9: Decreto 44 | C9: Ministerio de Economía, Fomento y Turismo | D9: 43151 | E9: APRUEBA REGLAMENTO QUE ESTABLECE REQUISITOS DE SEGURIDAD Y ROTULACIÓN DE EXTINTORES PORTÁTILES | F9: INSPECCION | G9: 45512 | H9: 1 | I9: N/A | J9: No Aplica | K9: Mensual | L9: Vigente. Última modificación 31-03-2020, Decreto 24 | M9: General | N9: S&ST
A10: 10 | B10: DS 67 | C10: Ministerio del Trabajo y Previsión Social; Subsecretaria de Previsión Social | D10: 36592 | E10: ='DS67'!B1 -> DS 67 APRUEBA REGLAMENTO PARA APLICACION DE ARTICULOS 15 Y 16 DE LEY Nº16.744, SOBRE EXENCIONES, REBAJAS Y RECARGOS DE LA COTIZACION ADICIONAL DIFERENCIADA | F10: REVISION DOCUMENTACION | G10: 45512 | H10: ='DS67'!B3 -> 1 | I10: N/A | J10: No Aplica | K10: Bianual | L10: Vigente. Última modificación 30-06-2023, Decreto 24 | M10: General | N10: S&ST
A11: 11 | B11: Ley 20949 | C11: Ministerio del Trabajo y Previsión Social | D11: 42630 | E11: ='Ley 20949'!B1 -> Ley 20949 MODIFICA EL CÓDIGO DEL TRABAJO PARA REDUCIR EL PESO DE LAS CARGAS DE MANIPULACIÓN MANUAL | F11: REVISION DOCUMENTACION | G11: 45512 | H11: ='Ley 20949'!B2 -> 1 | I11: N/A | J11: No Aplica | K11: Anual | L11: Vigente, versión única | M11: General | N11: S&ST
A12: 12 | B12: Decreto 63 | C12: Ministerio del Trabajo y Previsión Social; Subsecretaria de Previsión Social | D12: 38607 | E12: ='DS 63'!B1 -> Decreto 63 APRUEBA REGLAMENTO PARA LA APLICACION DE LA LEY Nº 20.001, QUE REGULA EL PESO MAXIMO DE CARGA HUMANA | F12: REVISION DOCUMENTACION | G12: 45512 | H12: ='DS 63'!B2 -> 1 | I12: N/A | J12: No Aplica | K12: Anual | L12: Vigente. Última modificación 17-01-2018, decreto 48 | M12: General | N12: S&ST
A13: 13 | B13: NCH N° 1411 | C13: Instituto Nacional de Normalización | E13: ='NCH1411'!B1 -> NCH Nº 1411 | F13: INSPECCION | G13: 45512 | H13: ='NCH1411'!B2 -> 1 | I13: N/A | J13: No Aplica | K13: Mensual | L13: Vigente parcial. Decreto N° 90. Ministerio de Transportes y Telecomunicaciones del 9-06-1993, nula y reemplaza la Norma NCh 1411/V.Of79- Prevención de riesgos - Parte V: Rotulado para el transporte marítimo de mercaderías peligrosas, declarada Oficial de la República de Chile, por Decreto N° 47 de 1979, del Ministerio de Salud. | M13: General | N13: S&ST
A14: 14 | B14: Ley 20005 | C14: Ministerio del Trabajo y Previsión Social; Subsecretaría del Trabajo | D14: 38429 | E14: ='LEY 20005'!B1 -> Ley 20005 Tipifica y sanciona el acoso sexual | F14: REVISION DOCUMENTACION | G14: 45512 | H14: ='LEY 20005'!B2 -> 1 | I14: N/A | J14: No Aplica | K14: Mensual | L14: Vigente, versión única | M14: General | N14: Calidad / S&ST
A15: 15 | B15: Ley 20096 | C15: Ministerio Secretaría General de la Presidencia | D15: 38799 | E15: ='LEY 20096'!B1 -> Ley 20096 Establece Mecanismos de Control Aplicables a las Sustancias Agotadoras de la Capa de Ozono | F15: REVISION DOCUMENTACION | G15: 45512 | H15: 1 | I15: N/A | J15: No Aplica | K15: Anual | L15: Vigente, versión única | M15: General | N15: Ambiente
A16: 16 | B16: DS 18 | C16: Ministerio de Salud Publica | D16: 30033 | E16: ='DS18'!B1 -> D.S. Nº 18 Certificacion de Calidad de EPP | F16: INSPECCION | G16: 45512 | H16: ='DS18'!B2 -> 1 | I16: N/A | J16: No Aplica | K16: Anual | L16: Vigente. Última versión 06-09-1995 | M16: General | N16: S&ST
A17: 17 | B17: DS 254 | C17: Ministerio de Salud | D17: 38014 | E17: ='DS254'!B1 -> D.S.Nº 254 Hoja de datos de seguridad de productos Quimicos | F17: INSPECCION | G17: 45512 | H17: ='DS254'!B2 -> 1 | I17: SI | J17: Cerrado | K17: Anual | L17: Vigente, versión única | M17: General | N17: Ambiente
A18: 18 | B18: DS 109 | C18: Ministerio del Trabajo y Previsión Social | D18: 24996 | E18: ='DS109'!B1 -> D.S.Nº 109 Evaluaciòn de accidente de trabajo y enfermedades profesionales | F18: REPORTE MUTUAL | G18: 45512 | H18: ='DS109'!B2 -> 1 | I18: N/A | J18: No Aplica | K18: Mensual | L18: Vigente. Última modificación 07-03-2006, Decreto 73 | M18: General | N18: S&ST
A19: 19 | B19: Ley 20.105 | C19: Ministerio de Salud; Subsecretaría de Salud Pública | D19: 38853 | E19: ='LEY20105'!B1 -> Ley Nº 19.419 REGULA ACTIVIDADES QUE INDICA RELACIONADAS CON EL TABACO | F19: REVISION DOCUMENTACION | G19: 45512 | H19: ='LEY20105'!B2 -> 1 | I19: N/A | J19: No Aplica | K19: Mensual | L19: Vigente, última modificación 01-02-2022, ley N° 21.413 | M19: General | N19: Ambiente / S&ST
A20: 20 | B20: Ley 20.047 | C20: Ministerio del Trabajo y Previsión Social; Subsecretaría del Trabajo | D20: 38597 | E20: ='LEY20047'!B1 -> Ley Nº 20.047 Establece permiso Paternal | F20: REVISION DOCUMENTACION | G20: 45512 | H20: ='LEY20047'!B2 -> 1 | I20: N/A | J20: No Aplica | K20: Mensual | L20: Vigente, versión única | M20: General | N20: Calidad / S&ST
A21: 21 | B21: DS 43 | C21: Ministerio de Salud | D21: 42458 | E21: ='DS43'!B1 -> DS 43 APRUEBA EL REGLAMENTO DE ALMACENAMIENTO DE SUSTANCIAS PELIGROSAS | F21: INSPECCION | G21: 45512 | H21: ='DS43'!B2 -> 1 | I21: SI | J21: Cerrado | K21: Semestral | L21: Vigente. Última modificación 17-08-2022, Decreto 60 | M21: General, siempre que DSS disponga de almacenamiento de sustancias que la norma califica como peligrosas | N21: Ambiente / S&ST
A22: 22 | B22: DFL 458 | C22: Ministerio de Vivienda y Urbanismo | D22: 27863 | E22: ='DS 458'!B1 -> DFL 458 APRUEBA NUEVA LEY GENERAL DE URBANISMO Y CONSTRUCCIONES | F22: REVISION DOCUMENTACION | G22: 45512 | H22: ='DS 458'!B2 -> 1 | I22: N/A | J22: No Aplica | K22: Mensual | L22: Vigente, última modificación 17/12/2023, ley 21.636 | M22: Particular, en las materias que se detallan en la pestaña respectiva | N22: Calidad
A23: 23 | B23: DS 47 | C23: Ministerio de Vivienda y Urbanismo | D23: 33760 | E23: ='DS 47'!B1 -> DS 47 FIJA NUEVO TEXTO DE LA ORDENANZA GENERAL DE LA LEY GENERAL DE URBANISMO Y CONSTRUCCIONES | F23: REVISION DOCUMENTACION | G23: 45512 | H23: ='DS 47'!B2 -> 1 | I23: N/A | J23: No Aplica | K23: Anual | L23: Vigente, última modificación 28/09/2023, Decreto 7 | M23: Particular, en las materias que se detallan en la pestaña respectiva | N23: Calidad
A24: 24 | B24: DFL 1 | C24: Ministerio del Trabajo y Previsión Social; Subsecretaría del Trabajo | D24: 37637 | E24: ='DFL1'!B1 -> D.F.L. Nº 1 FIJA EL TEXTO REFUNDIDO, COORDINADO Y SISTEMATIZADO DEL CÓDIGO DEL TRABAJO | F24: REVISION DOCUMENTACION | G24: 45512 | H24: ='DFL1'!B2 -> 1 | I24: N/A | J24: No Aplica | K24: Mensual | L24: Vigente, última modificación 21/06/2003, ley 21.592 (establece un estatuto de protección en favor del denunciante) | M24: General | N24: Calidad / S&ST
A25: 25 | B25: DFL 725 | C25: Ministerio de Salud Pública | D25: 24868 | E25: ='DFL 725 Codigo Sanitario'!B1 -> DFL 725 CODIGO SANITARIO | F25: REVISION DOCUMENTACION | G25: 45512 | H25: ='Ley 18490'!B2 -> 1 | I25: N/A | J25: No Aplica | K25: Mensual | L25: Vigente, última modificación 03-10-2023, Resolución Exenta N° 19.333 | M25: General | N25: Calidad / Ambiente / S&ST
A26: 26 | B26: Ley 18490 | C26: Ministerio de Hacienda | D26: 31416 | E26: ='Ley 18490'!B1 -> Ley 18490 ESTABLECE SEGURO OBLIGATORIO DE ACCIDENTES PERSONALES CAUSADOS POR CIRCULACION DE VEHICULOS MOTORIZADOS | F26: REVISION DOCUMENTACION | G26: 45512 | H26: ='Ley 18490'!B2 -> 1 | I26: N/A | J26: No Aplica | K26: Mensual | L26: Vigente, última modificación 09-01-2014, ley 20.720 | M26: General | N26: Calidad / S&ST
A27: 27 | B27: DS 609 | C27: Ministerio de Obras Públicas | D27: 38238 | E27: ESTABLECE NORMA DE EMISION PARA LA REGULACION DE CONTAMINANTES ASOCIADOS A LAS DESCARGAS DE RESIDUOS INDUSTRIALES LIQUIDOS A SISTEMAS DE ALCANTARILLADO | F27: REVISION DOCUMENTACION | G27: 45512 | H27: ='DS 601'!B2 -> 1 | I27: N/A | J27: No Aplica | K27: Anual | L27: Vigente. Última modificación 08-09-2004, Decreto 601 | M27: General | N27: Ambiente
A28: 28 | B28: Decreto 238 | C28: Ministerio de Relaciones Exteriores | D28: 32991 | E28: ='Decreto 238'!B1 -> PROMULGA PROTOCOLO DE MONTREAL RELATIVO A LAS SUSTANCIAS AGOTADORAS DE LA CAPA DE OZONO DE 16 DE SEPTIEMBRE DE 1987 | F28: REVISION DOCUMENTACION | G28: 45512 | H28: ='Decreto 238'!B2 -> 1 | I28: N/A | J28: No Aplica | K28: Anual | L28: Vigente, versión única | M28: General | N28: Ambiente
A29: 29 | B29: Decreto 55 | C29: Ministerio de Transportes y Telecomunicaciones | D29: 34440 | E29: ='Decreto 55'!B1 -> ESTABLECE NORMAS DE EMISION APLICABLES A VEHICULOS MOTORIZADOS PESADOS QUE INDICA | F29: REVISION DOCUMENTACION | G29: 45512 | H29: ='Decreto 55'!B2 -> 1 | I29: N/A | J29: No Aplica | K29: Anual | L29: Vigente. Última modificación 16/05/2012, Decreto 4 | M29: General | N29: Ambiente
A30: 30 | B30: Ley 20160 | C30: Ministerio de Economía, Fomento y Reconstrucción; Subsecretaría de Economía, Fomento y Reconstrucción | D30: 39108 | E30: ='Ley 20160'!B1 -> MODIFICA LA LEY Nº 19.039 SOBRE PROPIEDAD INDUSTRIAL | F30: REVISION DOCUMENTACION | G30: 45512 | H30: ='Ley 20160'!B2 -> 1 | I30: N/A | J30: No Aplica | K30: Anual | L30: Vigente, versión única | M30: General | N30: Calidad
A31: 31 | B31: Decreto 719 | C31: Ministerio de Relaciones Exteriores | D31: 32940 | E31: ='Decreto 719'!B1 -> PROMULGA EL CONVENIO DE VIENA PARA LA PROTECCION DE LA CAPA DE OZONO Y SUS ANEXOS I Y II | F31: REVISION DOCUMENTACION | G31: 45512 | H31: ='Decreto 719'!B2 -> 1 | I31: N/A | J31: No Aplica | K31: Anual | L31: Vigente, versión única | M31: General | N31: Ambiente
A32: 32 | B32: Ley 20435 | C32: Ministerio de Educación | D32: 40302 | E32: PROPIEDAD INTELECTUAL | F32: REVISION DOCUMENTACION | G32: 45512 | H32: 1 | I32: SI | J32: Cerrado | K32: Anual | L32: Vigente, versión única | M32: General | N32: Calidad
A33: 33 | B33: RES EX 218 | C33: Ministerio de Salud; Subsecretaría de Salud Pública; Instituto de Salud Pública | D33: 41310 | E33: ='RES EX 218'!B1 -> RESOLUCION EXENTA 218, MINISTERIO DE SALUD, APRUEBA INSTRUMENTO DE EVALUACION DE MEDIDAS PARA LA PREVENCION DE RIESGO PSICOSOCIALES EN EL TRABAJO | F33: EVALUACIONES | G33: 45512 | H33: ='RES EX 218'!B2 -> 1 | I33: SI | J33: Cerrado | K33: Anual | L33: Vigente, versión única | M33: General | N33: S&ST
A34: 34 | B34: RES EX 1448 | C34: Ministerio de Salud; Subsecretaría de Salud Pública | D34: 44859 | E34: ='RES EX 1448'!B1 -> RESOLUCION EXENTA 1448, MINISTERIO DE SALUD, SUBSECRETARIA DE SALUD PUBLICA, ACTUALIZA PROTOCOLO DE VIGILANCIA DE RIESGOS PSICOSOCIALES EN EL TRABAJO Y DEJA SIN EFECTO LA RESOLUCIÓN Nº 1.433 EXENTA, DE 2017, DEL MINISTERIO DE SALUD | F34: IMPLEMENTACION PROTOCOLO | G34: 45512 | H34: ='RES EX 1448'!B2 -> 1 | I34: SI | J34: Cerrado | K34: Anual | L34: Vigente, versión única | M34: General | N34: S&ST
A35: 35 | B35: NT TMERT | C35: Ministerio de Salud | D35: 41190 | E35: =TMERT!B1 -> NORMA TÉCNICA DE IDENTIFICACIÓN Y EVALUACIÓN DE FACTORES DE RIESGO DE TRASTORNOS MUSCULOESQUELÉTICOS RELACIONADOS AL TRABAJO (TMERT) | F35: EVALUACIONES | G35: 45512 | H35: =TMERT!B2 -> 1 | I35: N/A | J35: No Aplica | K35: Anual | L35: Vigente, versión única | M35: General | N35: S&ST
A36: 36 | B36: DS 1 | C36: Ministerio del Medio Ambiente | D36: 41396 | E36: ='DS 1 RECT'!B1 -> DS 1 APRUEBA REGLAMENTO DEL REGISTRO DE EMISIONES Y TRANSFERENCIAS DE CONTAMINANTES, RETC | F36: REVISION DOCUMENTACION | G36: 45512 | H36: ='DS 1 RECT'!B2 -> 1 | I36: N/A | J36: No Aplica | K36: Mensual | L36: Vigente. Última modificación 11-12-2018, Decreto 31 | M36: General | N36: Ambiente
A37: 37 | B37: Ordenanza 46 | C37: Ilustre Municipalidad de San Pedro de la Paz | D37: 41951 | E37: ='ORD MUN 46'!B1 -> Ordenanza Municipal N° 46 Gestión Ambiental Comunal | F37: INSPECCION | G37: 45512 | H37: ='ORD MUN 46'!B2 -> 1 | I37: N/A | J37: No Aplica | K37: Mensual | L37: Vigente, versión única | M37: General | N37: Ambiente
A38: 38 | B38: Ordenanza 56 | C38: Ilustre Municipalidad de San Pedro de la Paz | D38: 41661 | E38: ='ORD MUN 56'!B1 -> ORDENANZA 56, FIJASE EL SIGUIENTE TEXTO REFUNDIDO DE LA ORDENANZA LOCAL N°01, DE 24 DE DICIEMBRE 1996, QUE DETERMINA LA TARIFA DE ASEO DOMICILIARIO, SUS EXENCIONES Y EL COBRO ADICIONAL POR SOBREPRODUCCIÓN | F38: INSPECCION | G38: 45512 | H38: ='ORD MUN 56'!B2 -> 1 | I38: N/A | J38: No Aplica | K38: Anual | L38: Vigente, Última modificación 22-10-2014 | M38: General | N38: Ambiente
A39: 39 | B39: PRC San Pedro de la Paz | C39: Ilustre Municipalidad de San Pedro de la Paz | D39: 40598 | E39: ='Plan Regulador'!B1 -> PLAN REGULADOR COMUNAL SAN PEDRO DE LA PAZ DE 24 DE FEBRERO 2011 | F39: INSPECCION | G39: 45512 | H39: ='Plan Regulador'!B2 -> 1 | I39: N/A | J39: No Aplica | K39: Anual | L39: Vigente. Última modificación de 17 de enero de 2019, publicada en el Diario Oficial el 09 de febrero de 2019 | M39: General | N39: Calidad
A40: 40 | B40: DS 206 | C40: Ministerio del Trabajo y Previsión Social; Subsecretaria de Previsión Social | D40: 25865 | E40: ='DS 206'!B1 -> DS 206 de 1970 MODIFICA EL REGLAMENTO DE COMITES PARITARIOS DE HIGIENE Y SEGURIDAD | F40: REVISION DOCUMENTACION | G40: 45512 | H40: ='DS 206'!B2 -> 1 | I40: N/A | J40: No Aplica | K40: Anual | L40: Vigente, versión única | M40: General | N40: S&ST
...

Sheet Decreto 44
A1: CUERPO LEGAL | B1: APRUEBA NUEVO REGLAMENTO SOBRE GESTION PREVENTIVA DE LOS RIESGOS LABORALES PARA UN ENTORNO DE TRABAJO SEGURO Y SALUDABLE | C1: EVALUACION DE CUMPLIMIENTO
A2: CUMPLIMIENTO | B2: 0.9
A3: Articulos | B3: Ambito de Aplicación | C3: Frecuencia de Evaluación | D3: Cumple | E3: Parcial | F3: No Cumple | G3: N/A | H3: Registro o Forma de Evidenciar el Cumplimiento
A4: TODOS | B4: Decreto 44: MINISTERIO DEL TRABAJO Y PREVISIÓN SOCIAL, SUBSECRETARIA DE PREVISIÓN SOCIAL | C4: Anual | D4: 0.9 | H4: CUMPLIMIENTO CON IRL MIPER PLAN DE EMERGENCIA PLAN DE GESTION DE RIESGOS DE DESASTRES Y CATASTROFES MAPA DE RIESGOS Y RECURSOS (INTERNO) MAPA DE RIESGOS Y RECURSOS EXTERIOR

Sheet Decreto 160
A1: CUERPO LEGAL | B1: APRUEBA REGLAMENTO DE SEGURIDAD PARA LAS INSTALACIONES Y OPERACIONES DE PRODUCCIÓN Y REFINACIÓN, TRANSPORTE, ALMACENAMIENTO, DISTRIBUCIÓN Y ABASTECIMIENTO DE COMBUSTIBLES LÍQUIDOS | C1: EVALUACION DE CUMPLIMIENTO
A2: CUMPLIMIENTO | B2: =AVERAGE(D4:G4) -> 1
A3: Articulos | B3: Ambito de Aplicación | C3: Frecuencia de Evaluación | D3: Cumple | E3: Parcial | F3: No Cumple | G3: N/A | H3: Registro o Forma de Evidenciar el Cumplimiento
A4: TODOS | B4: Decreto 160: MINISTERIO DE ECONOMIA, FOMENTO Y RECONSTRUCCION, SUBSECRETARIA DE ECONOMIA FOMENTO Y RECONSTRUCCION: REGLAMENTO DE SEGURIDAD PARA LAS INSTALACIONES Y OPERACIONES DE PRODUCCIÓN Y REFINACIÓN, TRANSPORTE, ALMACENAMIENTO, DISTRIBUCIÓN Y ABASTECIMIENTO DE COMBUSTIBLES LÍQUIDOS | C4: Anual | D4: 1 | H4: Condiciones de almacenaje

Sheet Ley 21643
A1: CUERPO LEGAL | B1: 'MODIFICA EL CÓDIGO DEL TRABAJO Y OTROS CUERPOS LEGALES, EN MATERIA DE PREVENCIÓN, INVESTIGACIÓN Y SANCIÓN DEL ACOSO LABORAL, SEXUAL O DE VIOLENCIA EN EL TRABAJO | C1: EVALUACION DE CUMPLIMIENTO
A2: CUMPLIMIENTO | B2: =AVERAGE(D4:G4) -> 1
A3: Articulos | B3: Ambito de Aplicación | C3: Frecuencia de Evaluación | D3: Cumple | E3: Parcial | F3: No Cumple | G3: N/A | H3: Registro o Forma de Evidenciar el Cumplimiento
A4: TODOS | B4: Ley 21643: MINISTERIO DEL TRABAJO Y PREVISION SOCIAL: PREVENCION, INVESTIGACIÓN Y SANCIÓN DEL ACOSO LABORAL, SEXUAL O DE VIOLENCIA EN EL TRABAJO | C4: Anual | D4: 1 | H4: RIOHS Aplicación de protocolo

Sheet Ley 21645
A1: CUERPO LEGAL | B1: MODIFICA EL TÍTULO II DEL LIBRO II DEL CÓDIGO DEL TRABAJO "DE LA PROTECCIÓN A LA MATERNIDAD, PATERNIDAD Y VIDA FAMILIAR" Y REGULA UN RÉGIMEN DE TRABAJO A DISTANCIA Y TELETRABAJO EN LAS CONDICIONES QUE INDICA | C1: EVALUACION DE CUMPLIMIENTO
A2: CUMPLIMIENTO | B2: =AVERAGE(D4:G4) -> 1
A3: Articulos | B3: Ambito de Aplicación | C3: Frecuencia de Evaluación | D3: Cumple | E3: Parcial | F3: No Cumple | G3: N/A | H3: Registro o Forma de Evidenciar el Cumplimiento
A4: TODOS | B4: Ley 21645: MINISTERIO DEL TRABAJO Y PREVISION SOCIAL: DE LA PROTECCIÓN A LA MATERNIDAD, PATERNIDAD Y VIDA FAMILIAR" Y REGULA UN RÉGIMEN DE TRABAJO A DISTANCIA Y TELETRABAJO | C4: Anual | D4: 1 | H4: Verificación de contratos MIPER Teletrabajo ODI Teletrabajo

Sheet Ley 21561
A1: CUERPO LEGAL | B1: MODIFICA EL CODIGO DEL TRABAJO CON EL OBJETO DE REDUCIR LA JORNADA LABORAL | C1: EVALUACION DE CUMPLIMIENTO
A2: CUMPLIMIENTO | B2: =AVERAGE(D4:G4) -> 1
A3: Articulos | B3: Ambito de Aplicación | C3: Frecuencia de Evaluación | D3: Cumple | E3: Parcial | F3: No Cumple | G3: N/A | H3: Registro o Forma de Evidenciar el Cumplimiento
A4: TODOS | B4: Ley 21561: MINISTERIO DEL TRABAJO Y PREVISION SOCIAL: MODIFICA EL CODIGO DEL TRABAJO CON EL OBJETO DE REDUCIR LA JORNADA LABORAL | C4: Anual | D4: 1 | H4: Verificación de contratos y registros de hora

Sheet RES EX 144
A1: CUERPO LEGAL | B1: Resolución Exenta 144, APRUEBA NORMA BÁSICA PARA LA IMPLEMENTACIÓN DE MODIFICACIÓN AL REGLAMENTO DEL REGISTRO DE EMISIONES Y TRANSFERENCIAS DE CONTAMINANTES, RETC | C1: EVALUACION DE CUMPLIMIENTO
A2: CUMPLIMIENTO | B2: =AVERAGE(D4:G4) -> 1
A3: Articulos | B3: Ambito de Aplicación | C3: Frecuencia de Evaluación | D3: Cumple | E3: Parcial | F3: No Cumple | G3: N/A | H3: Registro o Forma de Evidenciar el Cumplimiento
A4: TODOS | B4: Resolucion Exenta 144, MINISTERIO DE MEDIO AMBIENTE, NORMA BÁSICA PARA LA IMPLEMENTACIÓN DE MODIFICACIÓN AL REGLAMENTO DEL REGISTRO DE EMISIONES Y TRANSFERENCIAS DE CONTAMINANTES, RETC | C4: Anual | D4: 1 | H4: Declaraciones en VU RETC, Retiro de RESPEL

Sheet ORD 1389 007 DT
A1: CUERPO LEGAL | B1: Dictamen Ordinario Nº 1389/007 de la Dirección del Trabajo. | C1: EVALUACION DE CUMPLIMIENTO
A2: CUMPLIMIENTO | B2: =AVERAGE(D4:G4) -> 1
A3: Articulos | B3: Ambito de Aplicación | C3: Frecuencia de Evaluación | D3: Cumple | E3: Parcial | F3: No Cumple | G3: N/A | H3: Registro o Forma de Evidenciar el Cumplimiento
A4: TODOS | B4: Fija sentido y alcance de la Ley N°21.220, de 26.03.2020 | C4: Anual | D4: 1 | H4: Contratos de trabajo

Sheet Ley 21217
A1: CUERPO LEGAL | B1: Ley Nº 19.983, que regula la transferencia y otorga mérito ejecutivo a copia de la factura. | C1: EVALUACION DE CUMPLIMIENTO
A2: CUMPLIMIENTO | B2: =AVERAGE(D4:G4) -> 1
A3: Articulos | B3: Ambito de Aplicación | C3: Frecuencia de Evaluación | D3: Cumple | E3: Parcial | F3: No Cumple | G3: N/A | H3: Registro o Forma de Evidenciar el Cumplimiento
A4: TODOS | B4: Regula transferencia y otorga mérito ejecutivo a copia de la factura. | C4: Anual | D4: 1 | H4: En ejercicio, Horarios, mantención funciones y cargos, recursos para funcionar.

Sheet Ley 21220
A1: CUERPO LEGAL | B1: Ley Nº 21.220, Modifica el Código del Trabajo en materia de trabajo a distancia. | C1: EVALUACION DE CUMPLIMIENTO
A2: CUMPLIMIENTO | B2: =AVERAGE(D4:G4) -> 1
A3: Articulos | B3: Ambito de Aplicación | C3: Frecuencia de Evaluación | D3: Cumple | E3: Parcial | F3: No Cumple | G3: N/A | H3: Registro o Forma de Evidenciar el Cumplimiento
A4: TODOS | B4: Modifica el Código del Trabajo en materia de trabajo a distancia. | C4: Anual | D4: 1 | H4: En ejercicio, Horarios, mantención funciones y cargos, recursos para funcionar.

Sheet Ley 21122
A1: CUERPO LEGAL | B1: MODIFICA EL CÓDIGO DEL TRABAJO EN MATERIA DE CONTRATO DE TRABAJO POR OBRA O FAENA | C1: EVALUACION DE CUMPLIMIENTO
A2: CUMPLIMIENTO | B2: =AVERAGE(D4:G4) -> 1
A3: Articulos | B3: Ambito de Aplicación | C3: Frecuencia de Evaluación | D3: Cumple | E3: Parcial | F3: No Cumple | G3: N/A | H3: Registro o Forma de Evidenciar el Cumplimiento
A4: TODOS | B4: Modifica Codigo del Trabajo en materia de trabajo por obra o faena | C4: Cada vez | D4: 1 | H4: Contratos

Sheet Ley 21018
A1: CUERPO LEGAL | B1: CONFIERE COMPETENCIA A LOS TRIBUNALES LABORALES PARA CONOCER DE LAS CONTIENDAS EN QUE, LOS CAUSAHABIENTES DEL TRABAJADOR, BUSCAN HACER EFECTIVA LA RESPONSABILIDAD DEL EMPLEADOR, DERIVADA DE ACCIDENTES DEL TRABAJO O ENFERMEDADES PROFESIONALES | C1: EVALUACION DE CUMPLIMIENTO
A2: CUMPLIMIENTO | B2: =AVERAGE(D4:G4) -> 1
A3: Articulos | B3: Ambito de Aplicación | C3: Frecuencia de Evaluación | D3: Cumple | E3: Parcial | F3: No Cumple | G3: N/A | H3: Registro o Forma de Evidenciar el Cumplimiento
A4: Artículo único | B4: "Artículo único.- Reemplázase la letra f) del artículo 420 del Código del Trabajo, por la siguiente: "f) los juicios iniciados por el propio trabajador o sus causahabientes, en que se pretenda hacer efectiva la responsabilidad contractual del empleador por los daños producidos como consecuencia de accidentes del trabajo o enfermedades profesionales. Respecto de la responsabilidad extracontractual se seguirán las reglas del artículo 69 de la ley Nº 16.744, y".". | C4: Cada vez que se presente producto de accidente o enfermedad profesional | D4: 1 | H4: Demanda Existente

Sheet NCh2245
A1: CUERPO LEGAL | B1: HOJA DE DATOS DE SEGURIDAD PARA PRODUCTOS QUIMICOS - CONTENIDO Y ORDEN DE LAS SECCIONES | C1: EVALUACION DE CUMPLIMIENTO
A2: CUMPLIMIENTO | B2: =AVERAGE(D4:G4) -> 1
A3: Articulos | B3: Ambito de Aplicación | C3: Frecuencia de Evaluación | D3: Cumple | E3: Parcial | F3: No Cumple | G3: N/A | H3: Registro o Forma de Evidenciar el Cumplimiento
A4: TODOS | B4: Documento que explica contenido y orden de secciones que debe contener una Hoja de Seguridad de productos con sustancias peligrosas dentro del territorio nacional. | C4: Semestral | D4: 1 | H4: Archivo de HDS

Sheet DS 100
A1: CUERPO LEGAL | B1: DECRETO SUPREMO 100 / 2005, MINISTERIO SECRETARIA GENERAL DE LA PRESIDENCIA, FIJA EL TEXTO REFUNDIDO, COORDINADO Y SISTEMATIZADO DE LA CONSTITUCION POLITICA DE LA REPUBLICA DE CHILE | C1: EVALUACION DE CUMPLIMIENTO
A2: CUMPLIMIENTO | B2: =AVERAGE(D4,D5,D6) -> 1
A3: Articulos | B3: Ambito de Aplicación | C3: Frecuencia de Evaluación | D3: Cumple | E3: Parcial | F3: No Cumple | G3: N/A | H3: Registro o Forma de Evidenciar el Cumplimiento
A4: Art. 19 | B4: La Constitución asegura a todas las personas: Nº8 El derecho a vivir en un medio ambiente libre de contaminación. Es deber del Estado velar para que este derecho no sea afectado y tutelar la preservación de la naturaleza. La ley podrá establecer restricciones específicas al ejercicio de determinados derechos o libertades para proteger el medio ambiente; | C4: Cada vez se genera una nueva incorporacion | D4: 1 | H4: Contrato de Trabajo, Entrega de RIOHS, Pago previsionales
A5: Art. 19 | B5: Nº9 El derecho a la protección de la salud. El estado protege el libre e igualitario acceso a las acciones de pomoción, protección y recuperación de la salud y de rehabilitación del individuo. le corresponderá, asimismo, la coordinación y control de las acciones relacionadas con la salud, sea que se presten a través de instituciones públicas o privadas, en la forma y condiciones que determine la ley, la que podrá establecer cotizaciones obligatorias. cada persona tendrá el derecho a elegir el sistema de salud al que desee acogerse, sea éste público o privado; | C5: Cada vez se genera una nueva incorporacion | D5: 1 | H5: Contrato de Trabajo, Entrega de RIOHS, Pago previsionales
A6: Art. 19 | B6: Nº18 El derecho a la seguridad social. Las leyes que regulen el ejercicio de este derecho serán de quorum calificado. La acción del Estado estará dirigida a garantizar el acceso de todos los habitantes al goce de prestaciones básicas uniformes. | C6: Mensual | D6: 1 | H6: Contrato de Trabajo, Entrega de RIOHS, Pago previsionales

Sheet Ley 16,744
A1: CUERPO LEGAL | B1: Ley Nº 16.744 "Establece Normas sobre Accidentes del Trabajo y Enfermedades Profesionales" | C1: EVALUACION DE CUMPLIMIENTO
A2: CUMPLIMIENTO | B2: =AVERAGE(D4:G16) -> 1
A3: Articulos | B3: Ambito de Aplicación | C3: Frecuencia de Evaluación | D3: Cumple | E3: Parcial | F3: No Cumple | G3: N/A | H3: Registro o Forma de Evidenciar el Cumplimiento
B4: Elaboración de REGLAMENTO INTERNO DE ORDEN, HIGIENE Y SEGURIDAD, contempla entre otras las siguientes modificaciones: -Jornadas de trabajo de 45 hrs. -Ley Nº 20949, sobre carga máxima humana -Ley Nº 20096, sobre protección solar -Ley Nº 20101, amplia concepto de Accidente de Trabajo modificaciones de D.S. 101, contiene el Reglamente General de la Ley Nª 16774. -Ley Nº20137 que 0torga permiso laboral por muerte y nacimiento de perientes que indica. -Ley Nº 20166 quw extiende el derecho de las madres trabajadoras a amamantar a sus hijos aún cuando no exista sala cuna. -Circular Nº 3705 de la Superintendencia de seguridad Social. | C4: Anual | D4: 1 | H4: Carpeta personal, Reglamento interno
A5: Artículo 4°.- | B5: La afiliación de un trabajador, hecha en una Caja de Previsión para los demás efectos de seguridad social, se entenderá hecha, por el ministerio de la ley, para este seguro, salvo que la entidad empleadora para la cual trabaje se encuentre adherida a alguna Mutualidad. Respecto de los trabajadores de contratistas o subcontratistas, deberán observarse, además, las siguientes reglas: El dueño de la obra, empresa o faena, será, subsidiariamente, responsable de las obligaciones que, en materia de afiliación y cotización, afecten a sus contratistas respecto de sus trabajadores. Igual responsabilidad afectará al contratista en relación con las obligaciones de sus subcontratistas. | C5: Cada vez que se contrate a un nuevo trabajador | D5: 1 | H5: Certificado de adhesión
A6: Artículo 5° | B6: Para los efectos de esta ley se entiende por accidente del trabajo toda lesión que una persona sufra a causa o con ocasión del trabajo, y que le produzca incapacidad o muerte. Son también accidentes del trabajo los ocurridos en el trayecto directo, de ida o regreso, entre la habitación y el lugar del trabajo, y aquéllos que ocurran en el trayecto directo entre dos lugares de trabajo, aunque correspondan a distintos empleadores. En este último caso, se considerará que el accidente dice relación con el trabajo al que se dirigía el trabajador al ocurrir el siniestro. Se considerarán también accidentes del trabajo los sufridos por dirigentes de instituciones sindicales a causa o con ocasión del desempeño de sus cometidos gremiales. Exceptúanse los accidentes debidos a fuerza mayor extraña que no tenga relación alguna con el trabajo y los producidos intencionalmente por la víctima. La prueba de las excepciones corresponderá al organismo administrador. | C6: Cada vez que se reporte un accidente | D6: 1 | H6: Registro Investigación de Accidente/DIAT
A7: Artículo 7°, inciso 1.- | B7: Es enfermedad profesional la causada de una manera directa por el ejercicio de la profesión o el trabajo que realice una persona y que le produzca incapacidad o muerte. | C7: Cada vez que se reporte una enfermedad | D7: 1 | H7: Protocolos en caso de enfermedad profesional, según infomación reportada por Mutual , DIEP
A8: Artículo 66° | B8: En toda industria o faena en que trabajen más de 25 personas deberán funcionar uno o más Comités Paritarios de Higiene y Seguridad, que tendrán las siguientes funciones: 1.- Asesorar e instruir a los trabajadores para la correcta utilización de los instrumentos de protección; 2.- Vigilar el cumplimiento, tanto por parte de las empresas como de los trabajadores, de las medidas de prevención, higiene y seguridad. 3.- Investigar las causas de los accidentes del trabajo y enfermedades profesionales, que se produzcan en la empresa y de cualquiera otra afección que afecte en forma reiterada o general a los trabajadores y sea presumible que tenga su origen en la utilización de productos fitosanitarios, químicos o nocivos para la salud; 4.- Indicar la adopción de todas las medidas de higiene y seguridad, que sirvan para la prevención de los riesgos profesionales; 5.- Cumplir las demás funciones o misiones que le encomiende el organismo administrador respectivo. El representante o los representantes de los trabajadores serán designados por los propios trabajadores. comerciales que ocupen a más de 100 trabajadores será obligatoria la existencia de un Departamento de Prevención de Riesgos Profesionales, el que será dirigido por un experto en prevención, el cual formará parte, por derecho propio, de los Comités Paritarios. Las empresas estarán obligadas a adoptar y poner en práctica las medidas de prevención que les indique el Departamento de Prevención y/o el Comité Paritario; pero podrán apelar de tales resoluciones ante el respectivo organismo administrador, dentro del plazo de 30 días, desde que le sea notificada la resolución del Departamento de Prevención o del Comité Paritario de Higiene y Seguridad. El i cumplimiento de las medidas acordadas por el Departamento de Prevención o por el Comité Paritario, cuando hayan sido ratificadas por el respectivo organismo administrador, será sancionado en la forma que preceptúa el artículo 68°. | C8: Anual | D8: 1 | H8: Constitución CPHS
A9: Art. 67 | B9: Las empresas estarán obligadas a mantener al día los reglamentos internos de higiene y seguridad en el trabajo y los trabajadores a cumplir con las exigencias de que dichos reglamentos les impongan. Los reglamentos deberán consultar la aplicación de multas a los trabajadores que no utilicen los elementos de protección personal que se les haya proporcionado o que no cumplan las obligaciones que les impónganlas normas, reglamentaciones o instrucciones sobre higiene y seguridad en el trabajo. | C9: Anual o cada vez que exista cambio o incorporación legal pertinente | D9: 1 | H9: Reglamento Interno
A10: Artículo 68°.- | B10: Las empresas o entidades deberán implantar todas las medidas de higiene y seguridad en el trabajo que les prescriban directamente el Servicio Nacional de Salud o, en su caso, el respectivo organismo administrador a que se encuentren afectas, el que deberá indicarlas de acuerdo con las normas y reglamentaciones vigentes. El i cumplimiento de tales obligaciones será sancionado por el Servicio Nacional de Salud de acuerdo con el procedimiento de multas y sanciones previsto en el Código Sanitario, y en las demás disposiciones legales, sin perjuicio de que el organismo administrador respectivo aplique, además, un recargo en la cotización adicional, en conformidad a lo dispuesto en la presente ley. Asimismo, las empresas deberán proporcionar a sus trabajadores, los equipos e implementos de protección necesarios, no pudiendo en caso alguno cobrarles su valor. Si no dieren cumplimiento a esta obligación serán sancionados en la forma que preceptúa el inciso anterior. El Servicio Nacional de Salud queda facultado para clausurar las fábricas, talleres, minas o cualquier sitio de trabajo que signifique un riesgo inminente para la salud de los trabajadores o de la comunidad. | C10: cada vez que seincorpore un nuevo trabajador | D10: 1 | H10: ODI, Entrega EPP, RIOHS
A11: Artículo 69°.- | B11: Cuando, el accidente o enfermedad se deba a culpa o dolo de la entidad empleadora o de un tercero, sin perjuicio de las acciones criminales que procedan, deberán observarse las siguientes reglas: a) El organismo administrador tendrá derecho a repetir en contra del responsable del accidente, por las prestaciones que haya otorgado o deba otorgar, y b) La víctima y las demás personas a quienes el accidente o enfermedad cause daño podrán reclamar al empleador o terceros responsables del accidente, también las otras indemnizaciones a que tengan derecho, con arreglo a las prescripciones del derecho común, incluso el daño moral. | C11: Cada vez que se produzca un accidente | D11: 1 | H11: Registro de investigacion de Accidente/DIAT
A12: Artículo 70°.- | B12: Si el accidente o enfermedad ocurre debido a negligencia inexcusable de un trabajador se le deberá aplicar una multa, de acuerdo con lo preceptuado en el artículo 68°, aún en el caso de que él mismo hubiere sido víctima del accidente. Corresponderá al Comité Paritario de Higiene y Seguridad decidir si medió negligencia inexcusable. | C12: Cada vez que se reporte por parte del organismo administrador una enfermedad profesional o accidente | D12: 1 | G12: -- | H12: Evaluación Mutual, informe investigación incidentes CPHS /DIAT /DIEP
A13: Artículo 71°.- | B13: Los afiliados afectados de alguna enfermedad profesional deberán ser trasladados, por la empresa donde presten sus servicios, a otras faenas donde no estén expuestos al agente causante de la enfermedad. Los trabajadores que sean citados para exámenes de control por los servicios médicos de los organismos administradores, deberán ser autorizados por su empleador para su asistencia, y el tiempo que en ello utilicen será considerado como trabajado para todos los efectos legales. Las empresas que exploten faenas en que trabajadores suyos puedan estar expuestos al riesgo de neumoconiosis, deberán realizar un control radiográfico semestral de tales trabajadores. | C13: Cada vez que exista el riesgo de una exposición a enfermedad profesional | D13: 1 | G13: -- | H13: Examenes pre-ocupacionales, ocupacionales
A14: Artículo 76° | B14: La entidad empleadora deberá denunciar al organismo administrador respectivo, inmediatamente de producido, todo accidente o enfermedad que pueda ocasionar incapacidad para el trabajo o la muerte de la víctima. El accidentado o enfermo, o sus derecho-habientes, o el médico que trató o diagnosticó la lesión o enfermedad, como igualmente el Comité Paritario de Seguridad, tendrán también, la obligación de denunciar el hecho en dicho organismo administrador, en el caso de que la entidad empleadora no hubiere realizado la denuncia. Las denuncias mencionadas en el inciso anterior deberán contener todos los datos que hayan sido indicados por el Servicio Nacional de Salud. Los organismos administradores deberán informar al Servicio Nacional de Salud los accidentes o enfermedades que les hubieren sido denunciados y que hubieren ocasionado incapacidad para el trabajo o la muerte de la víctima, en la forma y con la periodicidad que señale el reglamento. Sin perjuicio de lo dispuesto en los incisos precedentes, en caso de accidentes del trabajo fatales y graves, el empleador deberá informar inmediatamente a la Inspección del Trabajo y a la Secretaría Regional Ministerial de Salud que corresponda, acerca de la ocurrencia de cualquiera de estos hechos. Corresponderá a la Superintendencia de Seguridad Social impartir las instrucciones sobre la forma en que deberá cumplirse esta obligación. En estos mismos casos el empleador deberá suspender de forma inmediata las faenas afectadas y, de ser necesario, permitir a los trabajadores la evacuación del lugar de trabajo. La reanudación de faenas sólo podrá efectuarse cuando, previa fiscalización del organismo fiscalizador, se verifique que se han subsanado las deficiencias constatadas. Las infracciones a lo dispuesto en los incisos cuarto y quinto, serán sancionadas con multa a beneficio fiscal de cincuenta a ciento cincuenta unidades tributarias mensuales, las que serán aplicadas por los servicios fiscalizadores a que se refiere el inciso cuarto. | C14: Cada vez que se genere un accidente o enfermedad | D14: 1 | G14: -- | H14: DIAT - DIEP
A15: Artículo 77 bis.- | B15: El trabajador afectado por el rechazo de una licencia o de un reposo médico por parte de los organismos de los Servicios de Salud, de las Instituciones de Salud Previsional o de las Mutualidades de Empleadores, basado en que la afección invocada tiene o no tiene origen profesional, según el caso, deberá concurrir ante el organismo de régimen previsional a que esté afiliado, que no sea el que rechazó la licencia o el reposo médico, el cual estará obligado a cursarla de inmediato y a otorgar las prestaciones médicas o pecuniarias que correspondan, sin perjuicio de los reclamos posteriores y reembolsos, si procedieren, que establece este artículo. En la situación prevista en el inciso anterior, cualquier persona o entidad interesada podrá reclamar directamente en la Superintendencia de Seguridad Social por el rechazo de la licencia o del reposo médico, debiendo ésta resolver, con competencia exclusiva y sin ulterior recurso, sobre el carácter de la afección que dio origen a ella, en el plazo de treinta días contado desde la recepción de los antecedentes que se requieran o desde la fecha en que el trabajador afectado se hubiere sometido a los exámenes que disponga dicho Organismo, si éstos fueren posteriores. | C15: Cada vez que se genere un accidente | D15: 1 | G15: -- | H15: SUSESO
A16: Artículo 79°.- | B16: Las acciones para reclamar las prestaciones por accidentes del trabajo o enfermedades profesionales prescribirán en el término de cinco años contado desde la fecha del accidente o desde el diagnóstico de la enfermedad. En el caso de la neumoconiosis el plazo de prescripción será de quince años, contado desde que fue diagnosticada. Esta prescripción no correrá contra los menores de 16 años. | C16: Cada vez que se genere un accidente o enfermedad | D16: 1 | G16: -- | H16: SUSESO

Sheet DS148
A1: CUERPO LEGAL | B1: DS 148 APRUEBA REGLAMENTO SANITARIO SOBRE MANEJO DE RESIDUOS PELIGROSOS | C1: EVALUACION DE CUMPLIMIENTO
A2: CUMPLIMIENTO | B2: =AVERAGE(D5:G23) -> 1
A3: Articulos | B3: Ambito de Aplicación | C3: Frecuencia de Evaluación | D3: Cumple | E3: Parcial | F3: No Cumple | G3: N/A | H3: Registro o Forma de Evidenciar el Cumplimiento
A4: Art. 1 | B4: Este Reglamento establece las condiciones sanitarias y de seguridad mínimas a que deberá someterse la generación, tenencia, almacenamiento, transporte, tratamiento, reuso, reciclaje, disposición final y otras formas de eliminación de los residuos peligrosos. | C4: Anual | D4: 1 | H4: Registros Sidrep
A5: Art 4 | B5: Los residuos peligrosos deberan identificarse y etiquetarse de acuerdo a la clasificacion y tipo de riesgo que establece la NCH 2190 OF 93. Esta obligación será exigible desde que tales residuos se almacenen y hasta su eliminacion | C5: Semestral | D5: 1 | H5: Rotulado de residuos peligrosos
A6: Art 6, inciso 1° | B6: Durante el manejo de los residuos peligrosos se deberan tomar todas las precauciones necesarias para prevenir su inflamación o reacción entre ellas su separación y protección frente a cualquier fuente de riesgo capaz de provocar tales efectos | C6: Cada vez que se generen residuos peligrosos | D6: 1 | H6: Rotulado de residuos peligrosos
A7: Art 8 | B7: Artículo 8 Los contenedores de residuos peligrosos deberán cumplir con los siguientes requisitos: a) tener un espesor adecuado y estar construidos con materiales que sean resistentes al residuo almacenado y a prueba de filtraciones, b) estar diseñados para ser capaces de resistir los esfuerzos producidos durante su manipulación, así como durante la carga y descarga y el traslado de los residuos, garantizando en todo momento que no serán derramados, c) estar en todo momento en buenas condiciones, debiéndose reemplazar todos aquellos contenedores que muestren deterioro de su capacidad de contención, d) estar rotulados indicando, en forma claramente visible, las características de peligrosidad del residuo contenido de acuerdo a la Norma Chilena NCh 2.190 Of 93, el proceso en que se originó el residuo, el código de identificación y la fecha de su ubicación en el sitio de almacenamiento. Los contenedores sólo podrán ser movidos manualmente si su peso total incluido el contenido, no excede de 30 kilogramos. Si dicho peso fuere superior, se deberán mover con equipamiento mecánico. Sólo se podrán reutilizar contenedores cuando no se trate de residuos incompatibles, a menos que hayan sido previamente descontaminados. | C7: Anual | D7: 1 | H7: Resolución Sanitaria Bodega Residuos Peligrosos
A8: Art 9 | B8: Sólo se podrán mezclar o poner en contacto entre sí residuos peligrosos cuando sean de naturaleza similar o compatible. Para estos efectos la “Tabla de Incompatibilidades” del artículo 87 tendrá carácter referencial. Con todo, en los procesos de eliminación podrán mezclarse residuos de los grupos A y B de dicha Tabla, cuando se demuestre que los efectos de la reacción que ellos generan se encuentran bajo control. | C8: Anual | D8: 1 | H8: Resolución Sanitaria Bodega Residuos Peligrosos / Inspeccion APR
A9: Art 10 | B9: Un residuo o una mezcla de residuos es peligrosa si presenta riesgo para la salud pública y/o efectos adversos al medio ambiente ya sea directamente o debido a su manejo actual o previsto, como consecuencia de presentar alguna de las características que se definen en el artículo siguiente. | C9: Cada vez que se generen residuos peligrosos | D9: 1 | H9: Resolución Sanitaria Bodega Residuos Peligrosos / Inspeccion APR
A10: Art 15 | B10: Un residuo tendrá la característica de inflamabilidad si presenta cualquiera de las siguientes propiedades: a) Es líquido y presenta un punto de inflamación inferior a 61ºC en ensayos de copa cerrada o no superior a 65,6 ºC en ensayos de copa abierta. No incluyéndose en esta definición las soluciones acuosas con una concentración en volumen de alcohol inferior o igual al 24%. b) No es líquido y es capaz de provocar, bajo condiciones estándares de presión y temperatura (1 atm y 25 °C), fuego por fricción, por absorción de humedad o 10 cambios químicos espontáneos y, cuando se inflama, lo hace en forma tan vigorosa y persistente que ocasiona una situación de peligro. c) Es un gas comprimido inflamable. Se dice que un gas o una mezcla de gases es inflamable cuando al combinarse con aire constituye una mezcla que tiene un punto de inflamación inferior a 61°C. d) Es una sustancia oxidante, tal como los cloratos, permanganatos, peróxidos inorgánicos o nitratos, que genera oxígeno lo suficientemente rápido como para estimular la combustión de materia orgánica. | C10: Cada vez que se generen residuos peligrosos | D10: 1 | H10: Resolución Sanitaria Bodega Residuos Peligrosos / Inspeccion APR
A11: Artículo 18 | B11: Los residuos incluidos en los siguientes listados de categorías se considerarán peligrosos a menos que su generador pueda demostrar ante la Autoridad Sanitaria que no presentan ninguna característica de peligrosidad. El generador podrá proponer a la Autoridad Sanitaria los análisis de caracterización de peligrosidad a realizar sobre la base del conocimiento de sus residuos y de los procesos que los generan, sin perjuicio de lo cual, la Autoridad Sanitaria podrá exigir análisis adicionales a los propuestos conforme a lo señalado en los artículos 12 al 17. | C11: Cada vez que se generen residuos peligrosos | D11: 1 | H11: Resolución Sanitaria Bodega Residuos Peligrosos/ Registro de disposicion final
A12: Art 19 | B12: Los residuos incluidos en la Lista A del artículo 90 se considerarán igualmente peligrosos. No obstante el generador podrá demostrar ante la Autoridad Sanitaria, conforme a lo establecido en los artículos 12 al 17 del presente reglamento, que tales residuos no son peligrosos. A la inversa, se considerará que los residuos incluidos en la Lista B del artículo 90 no son peligrosos. La Autoridad Sanitaria tendrá siempre la facultad de comprobar que un residuo cualquiera es peligroso por presentar alguna característica de peligrosidad conforme a lo establecido en los artículos 12 al 17. | C12: Cada vez que se generen residuos peligrosos | D12: 1 | H12: Resolución Sanitaria Bodega Residuos Peligrosos / Inspeccion CPHS
A13: Artículo 21 | B13: Toda instalación, equipo o contenedor, o cualquiera de sus partes, que haya estado en contacto directo con residuos peligrosos, deberá ser manejado como tal y no podrá ser destinado a otro uso sin que haya sido previamente descontaminado. | C13: Cada vez que ocurra | D13: 1 | H13: Resolución Sanitaria Bodega Residuos Peligrosos / Inspeccion APR
A14: Artículo 22 | B14: Las sustancias químicas incluidas en los Artículos 88 y 89 del presente Reglamento, serán consideradas residuos peligrosos cuando sean descartadas, se encuentren vencidas o fuera de especificación o se encuentren como remanentes en envases y recipientes. Lo mismo procederá respecto de los derrames de cualquiera de dichas sustancias químicas y los materiales contaminados con ellas que deban desecharse. | C14: Cada vez que ocurra | D14: 1 | H14: Inspeccion APRS / Registro disposición final
A15: Artículo 25 | B15: Las instalaciones, establecimientos o actividades que anualmente den origen a más de 12 kilogramos de residuos tóxicos agudos o a más de 12 toneladas de residuos peligrosos que presenten cualquier otra característica de peligrosidad deberán contar con un Plan de Manejo de Residuos Peligrosos presentado ante la Autoridad Sanitaria. | C15: Anual | G15: 1 | H15: Resolución Sanitaria Bodega Residuos Peligrosos / Inspeccion APR
A16: Artículo 29 | B16: Todo sitio destinado al almacenamiento de residuos peligrosos deberá contar con la correspondiente autorización sanitaria de instalación, a menos que éste se encuentre incluido en la autorización sanitaria de la actividad principal. El diseño, la construcción, ampliación y/o modificación de todo sitio que implique almacenamiento de dos o más residuos peligrosos incompatibles o que contemple el almacenamiento de 12 o más kilogramos de residuos tóxicos agudos o 12 o más toneladas de residuos peligrosos que presenten cualquier otra característica de peligrosidad, deberá contar con un proyecto previamente aprobado por la Autoridad Sanitaria. Este proyecto de ingeniería deberá ser elaborado por un profesional idóneo. | C16: En proceso de validacion por Seremi Salud | G16: 1 | H16: Resolución Sanitaria Bodega Residuos Peligrosos / Inspeccion APR
A17: Artículo 31 | B17: El período de almacenamiento de los residuos peligrosos no podrá exceder de 6 meses. Sin embargo, en casos justificados, se podrá solicitar a la Autoridad Sanitaria, una extensión de dicho período hasta por un lapso igual, para lo cual se deberá presentar un informe técnico. | C17: Cada 5 meses desde la fecha de ingreso del primer residuo rotulado | D17: 1 | H17: Rotulado de residuos peligrosos
A18: Artículo 32 | B18: En caso de inexistencia de una Instalación de Eliminación, imposibilidad de acceso a ella u otros casos calificados, la Autoridad Sanitaria podrá autorizar el almacenamiento de residuos peligrosos por períodos prolongados determinados superiores a los establecidos en el artículo precedente. En este caso, el almacenamiento será considerado una Instalación de Eliminación de Residuos Peligrosos y se ajustará en todo a las normas establecidas en el Párrafo I del Título VI del presente Reglamento, sin perjuicio de la aplicación de las disposiciones especiales de este párrafo. Estas Instalaciones sólo podrán almacenar los residuos expresamente autorizados por la Autoridad Sanitaria, la que igualmente deberá autorizar el retiro total o parcial de éstos. | C18: Anual | D18: 1 | H18: Resolución Sanitaria Bodega Residuos Peligrosos
A19: Artículo 33 | B19: Los sitios donde se almacenen residuos peligrosos deberán cumplir las siguientes condiciones: a) Tener una base continua, impermeable y resistente estructural y químicamente a los residuos. b) Contar con un cierre perimetral de a lo menos 1,80 metros de altura que impida el libre acceso de personas y animales. c) Estar techados y protegidos de condiciones ambientales tales como humedad, temperatura y radiación solar. d) Garantizar que se minimizará la volatilización, el arrastre o la lixiviación y en general cualquier otro mecanismo de contaminación del medio ambiente que pueda afectar a la población. e) Tener una capacidad de retención de escurrimientos o derrames no inferior al volumen del contenedor de mayor capacidad ni al 20% del volumen total de los contenedores almacenados. f) Contar con señalización de acuerdo a la Norma Chilena NCh 2.190 Of 93 Excepcionalmente se podrán autorizar sitios de almacenamiento que no cumplan con alguna de estas condiciones, tales como piscinas, lagunas artificiales u otros, si se justifica técnicamente que su diseño protege de la misma forma la salud de la población. | C19: Anaul | D19: 1 | H19: Resolución Sanitaria Bodega Residuos Peligrosos
A20: Art 34 | B20: El sitio de almacenamiento debera tener acceso restingido,en terminos que solo podra ingresar personal debidamente autorizado por el responsable de la instalacion | C20: mensual | D20: 1 | H20: Resolución Sanitaria Bodega Residuos Peligrosos
A21: Artículo 35 | B21: El sitio de almacenamiento de residuos reactivos o inflamables, deberá estar a 15 metros, a lo menos, de los deslindes de la propiedad. | C21: Anual | D21: 1 | H21: Resolución Sanitaria Bodega Residuos Peligrosos
A22: Artículo 80 | B22: Los tenedores de residuos peligrosos quedan sujetos a un Sistema de Declaración y Seguimiento de tales residuos, válido para todo el país, que tiene por objeto permitir a la autoridad sanitaria disponer de información completa, actual y oportuna sobre la tenencia de tales residuos desde el momento que salen del establecimiento de generación hasta su recepción en una instalación de eliminación. Corresponderá a la Autoridad Sanitaria, en su respectivo territorio, implementar el sistema referido ajustándose a las normas del presente título y a las instrucciones que imparta el Ministerio de Salud. | C22: Semestral | D22: 1 | H22: Resolución Sanitaria Bodega Residuos Peligrosos / RETC
A23: Artículo 81 | B23: Desde que un residuo peligroso sale del establecimiento de generación deberá estar permanentemente acompañado del Documento de Declaración que Será responsable del cumplimiento del presente artículo el actual tenedor de los residuos sin perjuicio de otras responsabilidades.corresponde emitir al generador. | C23: Cada 5 meses/ o autorizacion SEREMI en caso de no contar con la cantidad sufiente de retiro | D23: 1 | H23: Resolución Sanitaria Bodega Residuos Peligrosos / RETC

Sheet DS 594
A1: CUERPO LEGAL | B1: DS 594 "Reglamento sobre condiciones sanitarias y ambientales básicas en los lugares de trabajo" | C1: EVALUACION DEL CUMPLIMIENTO
A2: CUMPLIMIENTO | B2: =AVERAGE(D5:G62) -> 1
A3: Articulos | B3: Ambito de Aplicación | C3: Frecuencia de Evaluación | D3: Cumple | E3: Parcial | F3: No Cumple | G3: N/A | H3: Registro o Forma de Evidenciar el Cumplimiento
A4: Artículo 1 | B4: El presente reglamento establece las condiciones sanitarias y ambientales básicas que deberá cumplir todo lugar de trabajo, sin perjuicio de la reglamentación específica que se haya dictado o se dicte para aquellas faenas que requieren condiciones especiales. Establece, además, los límites permisibles de exposición ambiental a agentes químicos y agentes físicos, y aquellos límites de tolerancia biológica para trabajadores expuestos a riesgo ocupacional. | C4: Anual
A5: Artículo 3° | B5: La empresa está obligada a mantener en los lugares de trabajo las condiciones sanitarias y ambientales necesarias para proteger la vida y la salud de los trabajadores que en ellos se desempeñan, sean éstos dependientes directos suyos o lo sean de terceros contratistas que realizan actividades para ella. | C5: Anual | D5: 1 | H5: Inspecciones APR y MUTUAL, cualitativo
A6: Artículo 4° | B6: La construcción, reconstrucción, alteración, modificación y reparación de los establecimientos y locales de trabajo en general, se regirán por la Ordenanza General de Urbanismo y Construcciones vigente. | C6: anual | D6: 1 | H6: Patente comercial
A7: Art. 5 | B7: Los Pavimentos y revestimientos de los piso serán, en general sólidos y no resbaladizos. En aquellos lugares de trabajo donde se almacene, fabriquen o manipulen productos toxicos corrosivos de cualquier naturaleza,los pisos deben ser de material resistente a estos, <impermeables y no porosos de tal manera que faciliten un alimpieza oportuna y completa. Cuando las operaciones o el proceso exopngan a la humedad del piso, existiran sistemas de drenaje u otros dispositivos que protejan a las pesonas contra la humedad. Para efectos del presente reglamento se entenderá por sustancias tóxicas, corrosivas, peligrosas, infecciosas, radiactivas, venenosas, explosivas o inflamables aquellas definidas en la Norma Oficial NCh 382:2013. | C7: anual | D7: 1 | H7: Inspecciones APR y MUTUAL, cualitativo
A8: Art.6 | B8: Las paredes interiores de los lugares de trabajo, los cielos rasos, puertas y ventanas y demás elementos estructurales, serán mantenidos en buen estado de limpieza y conservación, y será pintados, cuando el caso lo requiera, de acuerdo a la naturaleza de las labores que se ejecutan. | C8: anual | D8: 1 | H8: Inspecciones APR y MUTUAL, cualitativo
A9: Art.7 | B9: Los pisos de lugares de trabajo, así como los pasillo de tránsitos , se mantendrán libres de todo obstáculo que impida un fácil y seguro desplazamiento de los trabajadores, tanto en las tareas normales como en situaciones de emergencia. | C9: Mensual | D9: 1 | H9: Inspección CPHS
